[ 2023-10-05 15:59:46,982 ] 96 werkzeug - INFO - [31m[1mWARNING: This is a development server. Do not use it in a production deployment. Use a production WSGI server instead.[0m
 * Running on all addresses (0.0.0.0)
 * Running on http://127.0.0.1:5000
 * Running on http://192.168.1.123:5000
[ 2023-10-05 15:59:46,982 ] 96 werkzeug - INFO - [33mPress CTRL+C to quit[0m
[ 2023-10-05 15:59:54,701 ] 825 app - ERROR - Exception on /predictdata [GET]
Traceback (most recent call last):
  File "/Users/faraymajid/mlops_project/venv/lib/python3.8/site-packages/flask/app.py", line 1455, in wsgi_app
    response = self.full_dispatch_request()
  File "/Users/faraymajid/mlops_project/venv/lib/python3.8/site-packages/flask/app.py", line 869, in full_dispatch_request
    rv = self.handle_user_exception(e)
  File "/Users/faraymajid/mlops_project/venv/lib/python3.8/site-packages/flask/app.py", line 867, in full_dispatch_request
    rv = self.dispatch_request()
  File "/Users/faraymajid/mlops_project/venv/lib/python3.8/site-packages/flask/app.py", line 852, in dispatch_request
    return self.ensure_sync(self.view_functions[rule.endpoint])(**view_args)
  File "app.py", line 21, in predict_datapoint
    return render_template('home.html')
  File "/Users/faraymajid/mlops_project/venv/lib/python3.8/site-packages/flask/templating.py", line 152, in render_template
    return _render(app, template, context)
  File "/Users/faraymajid/mlops_project/venv/lib/python3.8/site-packages/flask/templating.py", line 133, in _render
    rv = template.render(context)
  File "/Users/faraymajid/mlops_project/venv/lib/python3.8/site-packages/jinja2/environment.py", line 1301, in render
    self.environment.handle_exception()
  File "/Users/faraymajid/mlops_project/venv/lib/python3.8/site-packages/jinja2/environment.py", line 936, in handle_exception
    raise rewrite_traceback_stack(source=source)
  File "/Users/faraymajid/mlops_project/templates/home.html", line 6, in top-level template code
    <form action="{{ url_for('predictdata')}}" method="post">
  File "/Users/faraymajid/mlops_project/venv/lib/python3.8/site-packages/flask/app.py", line 1071, in url_for
    return self.handle_url_build_error(error, endpoint, values)
  File "/Users/faraymajid/mlops_project/venv/lib/python3.8/site-packages/flask/app.py", line 1060, in url_for
    rv = url_adapter.build(  # type: ignore[union-attr]
  File "/Users/faraymajid/mlops_project/venv/lib/python3.8/site-packages/werkzeug/routing/map.py", line 919, in build
    raise BuildError(endpoint, values, method, self)
werkzeug.routing.exceptions.BuildError: Could not build url for endpoint 'predictdata'. Did you mean 'predict_datapoint' instead?
[ 2023-10-05 15:59:54,707 ] 96 werkzeug - INFO - 127.0.0.1 - - [05/Oct/2023 15:59:54] "[35m[1mGET /predictdata HTTP/1.1[0m" 500 -
[ 2023-10-05 15:59:59,313 ] 825 app - ERROR - Exception on /predictdata [GET]
Traceback (most recent call last):
  File "/Users/faraymajid/mlops_project/venv/lib/python3.8/site-packages/flask/app.py", line 1455, in wsgi_app
    response = self.full_dispatch_request()
  File "/Users/faraymajid/mlops_project/venv/lib/python3.8/site-packages/flask/app.py", line 869, in full_dispatch_request
    rv = self.handle_user_exception(e)
  File "/Users/faraymajid/mlops_project/venv/lib/python3.8/site-packages/flask/app.py", line 867, in full_dispatch_request
    rv = self.dispatch_request()
  File "/Users/faraymajid/mlops_project/venv/lib/python3.8/site-packages/flask/app.py", line 852, in dispatch_request
    return self.ensure_sync(self.view_functions[rule.endpoint])(**view_args)
  File "app.py", line 21, in predict_datapoint
    return render_template('home.html')
  File "/Users/faraymajid/mlops_project/venv/lib/python3.8/site-packages/flask/templating.py", line 152, in render_template
    return _render(app, template, context)
  File "/Users/faraymajid/mlops_project/venv/lib/python3.8/site-packages/flask/templating.py", line 133, in _render
    rv = template.render(context)
  File "/Users/faraymajid/mlops_project/venv/lib/python3.8/site-packages/jinja2/environment.py", line 1301, in render
    self.environment.handle_exception()
  File "/Users/faraymajid/mlops_project/venv/lib/python3.8/site-packages/jinja2/environment.py", line 936, in handle_exception
    raise rewrite_traceback_stack(source=source)
  File "/Users/faraymajid/mlops_project/templates/home.html", line 6, in top-level template code
    <form action="{{ url_for('predictdata')}}" method="post">
  File "/Users/faraymajid/mlops_project/venv/lib/python3.8/site-packages/flask/app.py", line 1071, in url_for
    return self.handle_url_build_error(error, endpoint, values)
  File "/Users/faraymajid/mlops_project/venv/lib/python3.8/site-packages/flask/app.py", line 1060, in url_for
    rv = url_adapter.build(  # type: ignore[union-attr]
  File "/Users/faraymajid/mlops_project/venv/lib/python3.8/site-packages/werkzeug/routing/map.py", line 919, in build
    raise BuildError(endpoint, values, method, self)
werkzeug.routing.exceptions.BuildError: Could not build url for endpoint 'predictdata'. Did you mean 'predict_datapoint' instead?
[ 2023-10-05 15:59:59,314 ] 96 werkzeug - INFO - 127.0.0.1 - - [05/Oct/2023 15:59:59] "[35m[1mGET /predictdata HTTP/1.1[0m" 500 -
